Error in proxy: Expecting value: line 1 column 1 (char 0)
Traceback (most recent call last):
  File "/home/alejandro/Desktop/binance_proxy/main.py", line 110, in proxy_to_binance
    content=response.json(),
            ^^^^^^^^^^^^^^^
  File "/home/alejandro/Desktop/binance_proxy/venv/lib/python3.12/site-packages/httpx/_models.py", line 832, in json
    return jsonlib.loads(self.content, **kwargs)
           ^^^^^^^^^^^^^^^^^^^^^^^^^^^^^^^^^^^^^
  File "/usr/lib/python3.12/json/__init__.py", line 346, in loads
    return _default_decoder.decode(s)
           ^^^^^^^^^^^^^^^^^^^^^^^^^^
  File "/usr/lib/python3.12/json/decoder.py", line 337, in decode
    obj, end = self.raw_decode(s, idx=_w(s, 0).end())
               ^^^^^^^^^^^^^^^^^^^^^^^^^^^^^^^^^^^^^^
  File "/usr/lib/python3.12/json/decoder.py", line 355, in raw_decode
    raise JSONDecodeError("Expecting value", s, err.value) from None
json.decoder.JSONDecodeError: Expecting value: line 1 column 1 (char 0)
Error: Expecting value: line 1 column 1 (char 0)
Traceback (most recent call last):
  File "/home/alejandro/Desktop/binance_proxy/venv/lib/python3.12/site-packages/starlette/middleware/errors.py", line 164, in __call__
    await self.app(scope, receive, _send)
  File "/home/alejandro/Desktop/binance_proxy/venv/lib/python3.12/site-packages/starlette/middleware/exceptions.py", line 63, in __call__
    await wrap_app_handling_exceptions(self.app, conn)(scope, receive, send)
  File "/home/alejandro/Desktop/binance_proxy/venv/lib/python3.12/site-packages/starlette/_exception_handler.py", line 53, in wrapped_app
    raise exc
  File "/home/alejandro/Desktop/binance_proxy/venv/lib/python3.12/site-packages/starlette/_exception_handler.py", line 42, in wrapped_app
    await app(scope, receive, sender)
  File "/home/alejandro/Desktop/binance_proxy/venv/lib/python3.12/site-packages/starlette/routing.py", line 716, in __call__
    await self.middleware_stack(scope, receive, send)
  File "/home/alejandro/Desktop/binance_proxy/venv/lib/python3.12/site-packages/starlette/routing.py", line 736, in app
    await route.handle(scope, receive, send)
  File "/home/alejandro/Desktop/binance_proxy/venv/lib/python3.12/site-packages/starlette/routing.py", line 290, in handle
    await self.app(scope, receive, send)
  File "/home/alejandro/Desktop/binance_proxy/venv/lib/python3.12/site-packages/starlette/routing.py", line 78, in app
    await wrap_app_handling_exceptions(app, request)(scope, receive, send)
  File "/home/alejandro/Desktop/binance_proxy/venv/lib/python3.12/site-packages/starlette/_exception_handler.py", line 53, in wrapped_app
    raise exc
  File "/home/alejandro/Desktop/binance_proxy/venv/lib/python3.12/site-packages/starlette/_exception_handler.py", line 42, in wrapped_app
    await app(scope, receive, sender)
  File "/home/alejandro/Desktop/binance_proxy/venv/lib/python3.12/site-packages/starlette/routing.py", line 75, in app
    response = await f(request)
               ^^^^^^^^^^^^^^^^
  File "/home/alejandro/Desktop/binance_proxy/venv/lib/python3.12/site-packages/fastapi/routing.py", line 302, in app
    raw_response = await run_endpoint_function(
                   ^^^^^^^^^^^^^^^^^^^^^^^^^^^^
  File "/home/alejandro/Desktop/binance_proxy/venv/lib/python3.12/site-packages/fastapi/routing.py", line 213, in run_endpoint_function
    return await dependant.call(**values)
           ^^^^^^^^^^^^^^^^^^^^^^^^^^^^^^
  File "/home/alejandro/Desktop/binance_proxy/main.py", line 110, in proxy_to_binance
    content=response.json(),
            ^^^^^^^^^^^^^^^
  File "/home/alejandro/Desktop/binance_proxy/venv/lib/python3.12/site-packages/httpx/_models.py", line 832, in json
    return jsonlib.loads(self.content, **kwargs)
           ^^^^^^^^^^^^^^^^^^^^^^^^^^^^^^^^^^^^^
  File "/usr/lib/python3.12/json/__init__.py", line 346, in loads
    return _default_decoder.decode(s)
           ^^^^^^^^^^^^^^^^^^^^^^^^^^
  File "/usr/lib/python3.12/json/decoder.py", line 337, in decode
    obj, end = self.raw_decode(s, idx=_w(s, 0).end())
               ^^^^^^^^^^^^^^^^^^^^^^^^^^^^^^^^^^^^^^
  File "/usr/lib/python3.12/json/decoder.py", line 355, in raw_decode
    raise JSONDecodeError("Expecting value", s, err.value) from None
json.decoder.JSONDecodeError: Expecting value: line 1 column 1 (char 0)
Error in proxy: 
Traceback (most recent call last):
  File "/home/alejandro/Desktop/binance_proxy/venv/lib/python3.12/site-packages/httpx/_transports/default.py", line 101, in map_httpcore_exceptions
    yield
  File "/home/alejandro/Desktop/binance_proxy/venv/lib/python3.12/site-packages/httpx/_transports/default.py", line 394, in handle_async_request
    resp = await self._pool.handle_async_request(req)
           ^^^^^^^^^^^^^^^^^^^^^^^^^^^^^^^^^^^^^^^^^^
  File "/home/alejandro/Desktop/binance_proxy/venv/lib/python3.12/site-packages/httpcore/_async/connection_pool.py", line 256, in handle_async_request
    raise exc from None
  File "/home/alejandro/Desktop/binance_proxy/venv/lib/python3.12/site-packages/httpcore/_async/connection_pool.py", line 236, in handle_async_request
    response = await connection.handle_async_request(
               ^^^^^^^^^^^^^^^^^^^^^^^^^^^^^^^^^^^^^^
  File "/home/alejandro/Desktop/binance_proxy/venv/lib/python3.12/site-packages/httpcore/_async/connection.py", line 101, in handle_async_request
    raise exc
  File "/home/alejandro/Desktop/binance_proxy/venv/lib/python3.12/site-packages/httpcore/_async/connection.py", line 78, in handle_async_request
    stream = await self._connect(request)
             ^^^^^^^^^^^^^^^^^^^^^^^^^^^^
  File "/home/alejandro/Desktop/binance_proxy/venv/lib/python3.12/site-packages/httpcore/_async/connection.py", line 124, in _connect
    stream = await self._network_backend.connect_tcp(**kwargs)
             ^^^^^^^^^^^^^^^^^^^^^^^^^^^^^^^^^^^^^^^^^^^^^^^^^
  File "/home/alejandro/Desktop/binance_proxy/venv/lib/python3.12/site-packages/httpcore/_backends/auto.py", line 31, in connect_tcp
    return await self._backend.connect_tcp(
           ^^^^^^^^^^^^^^^^^^^^^^^^^^^^^^^^
  File "/home/alejandro/Desktop/binance_proxy/venv/lib/python3.12/site-packages/httpcore/_backends/anyio.py", line 113, in connect_tcp
    with map_exceptions(exc_map):
  File "/usr/lib/python3.12/contextlib.py", line 158, in __exit__
    self.gen.throw(value)
  File "/home/alejandro/Desktop/binance_proxy/venv/lib/python3.12/site-packages/httpcore/_exceptions.py", line 14, in map_exceptions
    raise to_exc(exc) from exc
httpcore.ConnectTimeout

The above exception was the direct cause of the following exception:

Traceback (most recent call last):
  File "/home/alejandro/Desktop/binance_proxy/main.py", line 102, in proxy_to_binance
    response = await client.request(
               ^^^^^^^^^^^^^^^^^^^^^
  File "/home/alejandro/Desktop/binance_proxy/venv/lib/python3.12/site-packages/httpx/_client.py", line 1540, in request
    return await self.send(request, auth=auth, follow_redirects=follow_redirects)
           ^^^^^^^^^^^^^^^^^^^^^^^^^^^^^^^^^^^^^^^^^^^^^^^^^^^^^^^^^^^^^^^^^^^^^^
  File "/home/alejandro/Desktop/binance_proxy/venv/lib/python3.12/site-packages/httpx/_client.py", line 1629, in send
    response = await self._send_handling_auth(
               ^^^^^^^^^^^^^^^^^^^^^^^^^^^^^^^
  File "/home/alejandro/Desktop/binance_proxy/venv/lib/python3.12/site-packages/httpx/_client.py", line 1657, in _send_handling_auth
    response = await self._send_handling_redirects(
               ^^^^^^^^^^^^^^^^^^^^^^^^^^^^^^^^^^^^
  File "/home/alejandro/Desktop/binance_proxy/venv/lib/python3.12/site-packages/httpx/_client.py", line 1694, in _send_handling_redirects
    response = await self._send_single_request(request)
               ^^^^^^^^^^^^^^^^^^^^^^^^^^^^^^^^^^^^^^^^
  File "/home/alejandro/Desktop/binance_proxy/venv/lib/python3.12/site-packages/httpx/_client.py", line 1730, in _send_single_request
    response = await transport.handle_async_request(request)
               ^^^^^^^^^^^^^^^^^^^^^^^^^^^^^^^^^^^^^^^^^^^^^
  File "/home/alejandro/Desktop/binance_proxy/venv/lib/python3.12/site-packages/httpx/_transports/default.py", line 393, in handle_async_request
    with map_httpcore_exceptions():
  File "/usr/lib/python3.12/contextlib.py", line 158, in __exit__
    self.gen.throw(value)
  File "/home/alejandro/Desktop/binance_proxy/venv/lib/python3.12/site-packages/httpx/_transports/default.py", line 118, in map_httpcore_exceptions
    raise mapped_exc(message) from exc
httpx.ConnectTimeout
Error: 
Traceback (most recent call last):
  File "/home/alejandro/Desktop/binance_proxy/venv/lib/python3.12/site-packages/httpx/_transports/default.py", line 101, in map_httpcore_exceptions
    yield
  File "/home/alejandro/Desktop/binance_proxy/venv/lib/python3.12/site-packages/httpx/_transports/default.py", line 394, in handle_async_request
    resp = await self._pool.handle_async_request(req)
           ^^^^^^^^^^^^^^^^^^^^^^^^^^^^^^^^^^^^^^^^^^
  File "/home/alejandro/Desktop/binance_proxy/venv/lib/python3.12/site-packages/httpcore/_async/connection_pool.py", line 256, in handle_async_request
    raise exc from None
  File "/home/alejandro/Desktop/binance_proxy/venv/lib/python3.12/site-packages/httpcore/_async/connection_pool.py", line 236, in handle_async_request
    response = await connection.handle_async_request(
               ^^^^^^^^^^^^^^^^^^^^^^^^^^^^^^^^^^^^^^
  File "/home/alejandro/Desktop/binance_proxy/venv/lib/python3.12/site-packages/httpcore/_async/connection.py", line 101, in handle_async_request
    raise exc
  File "/home/alejandro/Desktop/binance_proxy/venv/lib/python3.12/site-packages/httpcore/_async/connection.py", line 78, in handle_async_request
    stream = await self._connect(request)
             ^^^^^^^^^^^^^^^^^^^^^^^^^^^^
  File "/home/alejandro/Desktop/binance_proxy/venv/lib/python3.12/site-packages/httpcore/_async/connection.py", line 124, in _connect
    stream = await self._network_backend.connect_tcp(**kwargs)
             ^^^^^^^^^^^^^^^^^^^^^^^^^^^^^^^^^^^^^^^^^^^^^^^^^
  File "/home/alejandro/Desktop/binance_proxy/venv/lib/python3.12/site-packages/httpcore/_backends/auto.py", line 31, in connect_tcp
    return await self._backend.connect_tcp(
           ^^^^^^^^^^^^^^^^^^^^^^^^^^^^^^^^
  File "/home/alejandro/Desktop/binance_proxy/venv/lib/python3.12/site-packages/httpcore/_backends/anyio.py", line 113, in connect_tcp
    with map_exceptions(exc_map):
  File "/usr/lib/python3.12/contextlib.py", line 158, in __exit__
    self.gen.throw(value)
  File "/home/alejandro/Desktop/binance_proxy/venv/lib/python3.12/site-packages/httpcore/_exceptions.py", line 14, in map_exceptions
    raise to_exc(exc) from exc
httpcore.ConnectTimeout

The above exception was the direct cause of the following exception:

Traceback (most recent call last):
  File "/home/alejandro/Desktop/binance_proxy/venv/lib/python3.12/site-packages/starlette/middleware/errors.py", line 164, in __call__
    await self.app(scope, receive, _send)
  File "/home/alejandro/Desktop/binance_proxy/venv/lib/python3.12/site-packages/starlette/middleware/exceptions.py", line 63, in __call__
    await wrap_app_handling_exceptions(self.app, conn)(scope, receive, send)
  File "/home/alejandro/Desktop/binance_proxy/venv/lib/python3.12/site-packages/starlette/_exception_handler.py", line 53, in wrapped_app
    raise exc
  File "/home/alejandro/Desktop/binance_proxy/venv/lib/python3.12/site-packages/starlette/_exception_handler.py", line 42, in wrapped_app
    await app(scope, receive, sender)
  File "/home/alejandro/Desktop/binance_proxy/venv/lib/python3.12/site-packages/starlette/routing.py", line 716, in __call__
    await self.middleware_stack(scope, receive, send)
  File "/home/alejandro/Desktop/binance_proxy/venv/lib/python3.12/site-packages/starlette/routing.py", line 736, in app
    await route.handle(scope, receive, send)
  File "/home/alejandro/Desktop/binance_proxy/venv/lib/python3.12/site-packages/starlette/routing.py", line 290, in handle
    await self.app(scope, receive, send)
  File "/home/alejandro/Desktop/binance_proxy/venv/lib/python3.12/site-packages/starlette/routing.py", line 78, in app
    await wrap_app_handling_exceptions(app, request)(scope, receive, send)
  File "/home/alejandro/Desktop/binance_proxy/venv/lib/python3.12/site-packages/starlette/_exception_handler.py", line 53, in wrapped_app
    raise exc
  File "/home/alejandro/Desktop/binance_proxy/venv/lib/python3.12/site-packages/starlette/_exception_handler.py", line 42, in wrapped_app
    await app(scope, receive, sender)
  File "/home/alejandro/Desktop/binance_proxy/venv/lib/python3.12/site-packages/starlette/routing.py", line 75, in app
    response = await f(request)
               ^^^^^^^^^^^^^^^^
  File "/home/alejandro/Desktop/binance_proxy/venv/lib/python3.12/site-packages/fastapi/routing.py", line 302, in app
    raw_response = await run_endpoint_function(
                   ^^^^^^^^^^^^^^^^^^^^^^^^^^^^
  File "/home/alejandro/Desktop/binance_proxy/venv/lib/python3.12/site-packages/fastapi/routing.py", line 213, in run_endpoint_function
    return await dependant.call(**values)
           ^^^^^^^^^^^^^^^^^^^^^^^^^^^^^^
  File "/home/alejandro/Desktop/binance_proxy/main.py", line 102, in proxy_to_binance
    response = await client.request(
               ^^^^^^^^^^^^^^^^^^^^^
  File "/home/alejandro/Desktop/binance_proxy/venv/lib/python3.12/site-packages/httpx/_client.py", line 1540, in request
    return await self.send(request, auth=auth, follow_redirects=follow_redirects)
           ^^^^^^^^^^^^^^^^^^^^^^^^^^^^^^^^^^^^^^^^^^^^^^^^^^^^^^^^^^^^^^^^^^^^^^
  File "/home/alejandro/Desktop/binance_proxy/venv/lib/python3.12/site-packages/httpx/_client.py", line 1629, in send
    response = await self._send_handling_auth(
               ^^^^^^^^^^^^^^^^^^^^^^^^^^^^^^^
  File "/home/alejandro/Desktop/binance_proxy/venv/lib/python3.12/site-packages/httpx/_client.py", line 1657, in _send_handling_auth
    response = await self._send_handling_redirects(
               ^^^^^^^^^^^^^^^^^^^^^^^^^^^^^^^^^^^^
  File "/home/alejandro/Desktop/binance_proxy/venv/lib/python3.12/site-packages/httpx/_client.py", line 1694, in _send_handling_redirects
    response = await self._send_single_request(request)
               ^^^^^^^^^^^^^^^^^^^^^^^^^^^^^^^^^^^^^^^^
  File "/home/alejandro/Desktop/binance_proxy/venv/lib/python3.12/site-packages/httpx/_client.py", line 1730, in _send_single_request
    response = await transport.handle_async_request(request)
               ^^^^^^^^^^^^^^^^^^^^^^^^^^^^^^^^^^^^^^^^^^^^^
  File "/home/alejandro/Desktop/binance_proxy/venv/lib/python3.12/site-packages/httpx/_transports/default.py", line 393, in handle_async_request
    with map_httpcore_exceptions():
  File "/usr/lib/python3.12/contextlib.py", line 158, in __exit__
    self.gen.throw(value)
  File "/home/alejandro/Desktop/binance_proxy/venv/lib/python3.12/site-packages/httpx/_transports/default.py", line 118, in map_httpcore_exceptions
    raise mapped_exc(message) from exc
httpx.ConnectTimeout
2025-07-27 22:37:54 - ERROR - Error: 'float' object has no attribute 'strftime'
Traceback (most recent call last):
  File "/home/alejandro/Desktop/dryback/venv/lib/python3.12/site-packages/starlette/middleware/errors.py", line 162, in __call__
    await self.app(scope, receive, _send)
  File "/home/alejandro/Desktop/dryback/venv/lib/python3.12/site-packages/starlette/middleware/exceptions.py", line 79, in __call__
    raise exc
  File "/home/alejandro/Desktop/dryback/venv/lib/python3.12/site-packages/starlette/middleware/exceptions.py", line 68, in __call__
    await self.app(scope, receive, sender)
  File "/home/alejandro/Desktop/dryback/venv/lib/python3.12/site-packages/fastapi/middleware/asyncexitstack.py", line 20, in __call__
    raise e
  File "/home/alejandro/Desktop/dryback/venv/lib/python3.12/site-packages/fastapi/middleware/asyncexitstack.py", line 17, in __call__
    await self.app(scope, receive, send)
  File "/home/alejandro/Desktop/dryback/venv/lib/python3.12/site-packages/starlette/routing.py", line 718, in __call__
    await route.handle(scope, receive, send)
  File "/home/alejandro/Desktop/dryback/venv/lib/python3.12/site-packages/starlette/routing.py", line 276, in handle
    await self.app(scope, receive, send)
  File "/home/alejandro/Desktop/dryback/venv/lib/python3.12/site-packages/starlette/routing.py", line 66, in app
    response = await func(request)
               ^^^^^^^^^^^^^^^^^^^
  File "/home/alejandro/Desktop/dryback/venv/lib/python3.12/site-packages/fastapi/routing.py", line 274, in app
    raw_response = await run_endpoint_function(
                   ^^^^^^^^^^^^^^^^^^^^^^^^^^^^
  File "/home/alejandro/Desktop/dryback/venv/lib/python3.12/site-packages/fastapi/routing.py", line 191, in run_endpoint_function
    return await dependant.call(**values)
           ^^^^^^^^^^^^^^^^^^^^^^^^^^^^^^
  File "/home/alejandro/Desktop/dryback/main.py", line 49, in get_status
    return {"uptime": uptime.strftime("%d:%H:%M:%S")}
                      ^^^^^^^^^^^^^^^
AttributeError: 'float' object has no attribute 'strftime'
2025-07-27 22:38:01 - ERROR - Error: 'float' object has no attribute 'strftime'
Traceback (most recent call last):
  File "/home/alejandro/Desktop/dryback/venv/lib/python3.12/site-packages/starlette/middleware/errors.py", line 162, in __call__
    await self.app(scope, receive, _send)
  File "/home/alejandro/Desktop/dryback/venv/lib/python3.12/site-packages/starlette/middleware/exceptions.py", line 79, in __call__
    raise exc
  File "/home/alejandro/Desktop/dryback/venv/lib/python3.12/site-packages/starlette/middleware/exceptions.py", line 68, in __call__
    await self.app(scope, receive, sender)
  File "/home/alejandro/Desktop/dryback/venv/lib/python3.12/site-packages/fastapi/middleware/asyncexitstack.py", line 20, in __call__
    raise e
  File "/home/alejandro/Desktop/dryback/venv/lib/python3.12/site-packages/fastapi/middleware/asyncexitstack.py", line 17, in __call__
    await self.app(scope, receive, send)
  File "/home/alejandro/Desktop/dryback/venv/lib/python3.12/site-packages/starlette/routing.py", line 718, in __call__
    await route.handle(scope, receive, send)
  File "/home/alejandro/Desktop/dryback/venv/lib/python3.12/site-packages/starlette/routing.py", line 276, in handle
    await self.app(scope, receive, send)
  File "/home/alejandro/Desktop/dryback/venv/lib/python3.12/site-packages/starlette/routing.py", line 66, in app
    response = await func(request)
               ^^^^^^^^^^^^^^^^^^^
  File "/home/alejandro/Desktop/dryback/venv/lib/python3.12/site-packages/fastapi/routing.py", line 274, in app
    raw_response = await run_endpoint_function(
                   ^^^^^^^^^^^^^^^^^^^^^^^^^^^^
  File "/home/alejandro/Desktop/dryback/venv/lib/python3.12/site-packages/fastapi/routing.py", line 191, in run_endpoint_function
    return await dependant.call(**values)
           ^^^^^^^^^^^^^^^^^^^^^^^^^^^^^^
  File "/home/alejandro/Desktop/dryback/main.py", line 49, in get_status
    return {"uptime": uptime.strftime("%d:%H:%M:%S")}
                      ^^^^^^^^^^^^^^^
AttributeError: 'float' object has no attribute 'strftime'
2025-07-27 22:39:24 - ERROR - Error: 'float' object has no attribute 'strftime'
Traceback (most recent call last):
  File "/home/alejandro/Desktop/dryback/venv/lib/python3.12/site-packages/starlette/middleware/errors.py", line 162, in __call__
    await self.app(scope, receive, _send)
  File "/home/alejandro/Desktop/dryback/venv/lib/python3.12/site-packages/starlette/middleware/exceptions.py", line 79, in __call__
    raise exc
  File "/home/alejandro/Desktop/dryback/venv/lib/python3.12/site-packages/starlette/middleware/exceptions.py", line 68, in __call__
    await self.app(scope, receive, sender)
  File "/home/alejandro/Desktop/dryback/venv/lib/python3.12/site-packages/fastapi/middleware/asyncexitstack.py", line 20, in __call__
    raise e
  File "/home/alejandro/Desktop/dryback/venv/lib/python3.12/site-packages/fastapi/middleware/asyncexitstack.py", line 17, in __call__
    await self.app(scope, receive, send)
  File "/home/alejandro/Desktop/dryback/venv/lib/python3.12/site-packages/starlette/routing.py", line 718, in __call__
    await route.handle(scope, receive, send)
  File "/home/alejandro/Desktop/dryback/venv/lib/python3.12/site-packages/starlette/routing.py", line 276, in handle
    await self.app(scope, receive, send)
  File "/home/alejandro/Desktop/dryback/venv/lib/python3.12/site-packages/starlette/routing.py", line 66, in app
    response = await func(request)
               ^^^^^^^^^^^^^^^^^^^
  File "/home/alejandro/Desktop/dryback/venv/lib/python3.12/site-packages/fastapi/routing.py", line 274, in app
    raw_response = await run_endpoint_function(
                   ^^^^^^^^^^^^^^^^^^^^^^^^^^^^
  File "/home/alejandro/Desktop/dryback/venv/lib/python3.12/site-packages/fastapi/routing.py", line 191, in run_endpoint_function
    return await dependant.call(**values)
           ^^^^^^^^^^^^^^^^^^^^^^^^^^^^^^
  File "/home/alejandro/Desktop/dryback/main.py", line 49, in get_status
    return {"uptime": str(uptime.strftime("%d:%H:%M:%S"))}
                          ^^^^^^^^^^^^^^^
AttributeError: 'float' object has no attribute 'strftime'
2025-07-27 22:40:30 - ERROR - Error: 'str' object has no attribute 'strftime'
Traceback (most recent call last):
  File "/home/alejandro/Desktop/dryback/venv/lib/python3.12/site-packages/starlette/middleware/errors.py", line 162, in __call__
    await self.app(scope, receive, _send)
  File "/home/alejandro/Desktop/dryback/venv/lib/python3.12/site-packages/starlette/middleware/exceptions.py", line 79, in __call__
    raise exc
  File "/home/alejandro/Desktop/dryback/venv/lib/python3.12/site-packages/starlette/middleware/exceptions.py", line 68, in __call__
    await self.app(scope, receive, sender)
  File "/home/alejandro/Desktop/dryback/venv/lib/python3.12/site-packages/fastapi/middleware/asyncexitstack.py", line 20, in __call__
    raise e
  File "/home/alejandro/Desktop/dryback/venv/lib/python3.12/site-packages/fastapi/middleware/asyncexitstack.py", line 17, in __call__
    await self.app(scope, receive, send)
  File "/home/alejandro/Desktop/dryback/venv/lib/python3.12/site-packages/starlette/routing.py", line 718, in __call__
    await route.handle(scope, receive, send)
  File "/home/alejandro/Desktop/dryback/venv/lib/python3.12/site-packages/starlette/routing.py", line 276, in handle
    await self.app(scope, receive, send)
  File "/home/alejandro/Desktop/dryback/venv/lib/python3.12/site-packages/starlette/routing.py", line 66, in app
    response = await func(request)
               ^^^^^^^^^^^^^^^^^^^
  File "/home/alejandro/Desktop/dryback/venv/lib/python3.12/site-packages/fastapi/routing.py", line 274, in app
    raw_response = await run_endpoint_function(
                   ^^^^^^^^^^^^^^^^^^^^^^^^^^^^
  File "/home/alejandro/Desktop/dryback/venv/lib/python3.12/site-packages/fastapi/routing.py", line 191, in run_endpoint_function
    return await dependant.call(**values)
           ^^^^^^^^^^^^^^^^^^^^^^^^^^^^^^
  File "/home/alejandro/Desktop/dryback/main.py", line 49, in get_status
    return {"uptime": str(uptime).strftime("%d:%H:%M:%S"), "status": "running"}
                      ^^^^^^^^^^^^^^^^^^^^
AttributeError: 'str' object has no attribute 'strftime'
